<?xml version="1.0"?>
<robot name="differential_robot">


	<link name="base_link">
		<visual>
			<geometry>
				<cylinder radius="0.175" length="0.04" />
			</geometry>
			<origin xyz="0 0 0.02" rpy="0 0 0" />
		</visual>
	</link>

	<link name="head">
		<visual>
			<geometry>
				<box size="0.06 0.06 0.06" />
			</geometry>
			<origin xyz="0.1 0 0.06" rpy="0 0 0" />
		</visual>
	</link>

	<link name="left_wheel">
		<visual>
			<geometry>
				<cylinder radius="0.07" length="0.015" />
			</geometry>
			<origin xyz="0 -0.170 0.02" rpy="1.57 0 0" />
		</visual>
	</link>

	<link name="right_wheel">
		<visual>
			<geometry>
				<cylinder radius="0.07" length="0.015" />
			</geometry>
			<origin xyz="0 00.170 0.02" rpy="1.57 0 0" />
		</visual>
	</link>

	<joint name="base_link_head_joint" type="fixed">
		<parent link="base_link" />
		<child link="head" />
		<origin xyz="0.1 0 0.075" rpy="0 0 0" />
	</joint>

	<joint name="base_link_left_wheel_joint" type="continuous">
		<parent link="base_link" />
		<child link="left_wheel" />
		<origin xyz="0 -0.170 0.02" rpy="1.57 0 0" />
		<axis xyz="1 0 0" />
	</joint>

	<joint name="base_link_right_wheel_joint" type="continuous">
		<parent link="base_link" />
		<child link="right_wheel" />
		<origin xyz="0 0.170 0.02" rpy="1.57 0 0" />
		<axis xyz="1 0 0" />
	</joint>


	
</robot>
